In sub-script
Successs got test
Success in finally
calling throw function
in fun_throws
Success caught <foo/>
